Workbook

Sheet Read Me
A1: Standard Parts Master for Pressure Vessels & Heat Exchangers
A2: HE + PV SOURCE MASTER — PROPOSED BASELINES COMPLETE FOR REVIEW, NOT APPROVED FOR TRACKER LOAD
A3: The approved HP Air Receiver GA has been added as a light-yellow PV dataset: 48 BOM lines, 30 new part families, 155 route steps and 31 assembly steps. Drawing facts are controlled in PV Drawing Basis; proposed time norms and shop methods remain on HOLD pending Production Head/PPC approval.
A5: Document control
A6: Prepared by
A7: Checked by (Production Head)
A8: Date
A10: Why we need this
A11: Every job's BOM is different, but the parts it is made of repeat. This master is the list of all standard parts and how each one is made. When a new job is created, parts will be selected from this list and job-specific sizes and quantities entered. The tracker then creates the production steps for each part, tracks them department-wise, rolls progress up to the equipment stages and calculates weights.
A13: Sheets
A14: Parts Master | B14: One row per standard part: equipment, group, make/buy, raw material, MOC, dimensions to enter, weight basis, spare, who filled/checked it, status.
A15: Part Routes | B15: One row per manufacturing step: operation, department, the equipment stage it counts toward, standard time, conditions, acceptance standard, record.
A16: Assembly Sequence | B16: How parts are joined into sub-assemblies and the complete equipment, with weld joint references.
A17: New Operations | B17: Steps that do not fit any operation in the fixed list, with the reason.
A18: HE Stages | B18: Whole-equipment stages for heat exchangers, with durations and predecessors.
A19: PV Stages (ref) | B19: The 36 PV stages already used in the tracker, for reference only.
A20: Material Master | B20: Density for every material.
A21: SP40 Drawing Basis | B21: Traceability register for the 25-page SP40 MED Train 1 drawing package, including exact design facts, drawing-required operations and unresolved controls.
A22: How to fill
A23: 1 | B23: Start with these 10 pilot parts: Shell Course, Dished End, Nozzle Neck, Nozzle Flange, Tube Sheet, Tube, Baffle, Saddle, Stud with Two Nuts, Gasket. Send the file back so we can review it together before the full list.
A24: 2 | B24: Fill 'HE Stages' first. Part Routes and Assembly Sequence need its stage numbers.
A25: 3 | B25: Use only the operations in the dropdown. If a step does not fit, add it to 'New Operations'. Please don't rename an existing operation.
A26: 4 | B26: Number steps 10, 20, 30… so steps can be inserted later without renumbering.
A27: 5 | B27: For every step, fill the stage number it counts toward: PV stage, HE stage, or both if the part is used in both.
A28: 6 | B28: If a part can be made in more than one way, give each way a variant letter (A, B) and list the steps for each.
A29: 7 | B29: If a step applies only sometimes, set Conditional = Yes and write the rule.
A30: 8 | B30: Give standard time for every step with its unit and basis (per piece, per metre of weld, per tube…).
A31: 9 | B31: Set 'Route Source' honestly. 'Assumed – to be confirmed' is allowed, but those parts cannot be approved until confirmed.
A32: 10 | B32: Only parts with Status = 'Approved by Production Head' will be loaded into the tracker.
A34: Colour legend
A35: Grey rows | B35: Example only. Replace or delete once your data is in.
A36: Yellow cells | B36: To be filled by the team.
A37: Blue cells | B37: Filled automatically. Do not type here.
A38: Green rows | B38: Reference data from the tracker. Do not edit.
A39: Orange cells | B39: Proposed planning value or approval-sensitive control. Validate before tracker load.
A40: PV Drawing Basis | B40: Approved GA metadata, design data, nozzle schedule and all 48 BOM lines with master-code traceability.
A41: PV Review | B41: Live PV completeness controls, design summary and approval gates.
A42: Light-yellow PV rows | B42: Drawing-backed pressure-vessel entries or proposed planning values requiring joint review.
A43: Orange PV cells | B43: Ambiguous source value, unapproved standard time, or approval-sensitive control.

Sheet Parts Master
A1: HE + PV MASTER — LIGHT-YELLOW PV ROWS ARE DRAWING-BACKED OR PROPOSED; ALL DRAFT ROUTES/TIMES REQUIRE PRODUCTION HEAD APPROVAL.
A2: One row per standard part. Part Code is your choice (suggested: 3-letter group + number). 'Filled by' and 'Checked by' must be real names; only parts with Status = 'Approved by Production Head' will be loaded into the tracker. The three blue columns check your entries automatically: 'Steps entered' must not be 0, and the other two should be 0 before approval.
A4: Example? | B4: Part Code | C4: Part Name | D4: Equipment | E4: Assembly Group | F4: Make / Buy | G4: Raw Material Form | H4: Typical MOC | I4: Dimensions to enter per job | J4: Weight Basis | K4: Route Variants (A, B…) | L4: Also a Spare? | M4: Route Source | N4: Filled by | O4: Checked by | P4: Status | Q4: Remarks | R4: Steps entered (auto) | S4: Steps missing stage no. (auto) | T4: Steps marked 'Assumed' (auto)
A5: PILOT – SOURCE DRAFT | B5: SHL-01 | C5: Shell Course | D5: PV + HE | E5: Shell | F5: Made in-house | G5: Plate | H5: SA240 S32205 | I5: ID 3000; thickness 10; developed length 9456; course width/length per job | J5: Rolled shell (ID, T, L) | K5: A | L5: No | M5: Assumed – to be confirmed | N5: Precise Engineers | O5: Pending – Production Head | P5: Draft | Q5: SP40 overall material list: ten shell plates, PL.10 THK × 9456 developed length; widths 1240, 1490 and 560. Route remains unapproved. PV drawing item 101: SA516 Gr.70 shell, 45T × 3750W × 7509 developed length; 9947 kg. | R5: =IF(B5="","",COUNTIF('Part Routes'!$B:$B,B5)) -> 9 | S5: =IF(B5="","",IF(D5="PV",COUNTIFS('Part Routes'!$B:$B,B5,'Part Routes'!$I:$I,""),IF(D5="HE",COUNTIFS('Part Routes'!$B:$B,B5,'Part Routes'!$J:$J,""),COUNTIFS('Part Routes'!$B:$B,B5,'Part Routes'!$I:$I,"")+COUNTIFS('Part Routes'!$B:$B,B5,'Part Routes'!$J:$J,"")))) -> 0 | T5: =IF(B5="","",IF(M5="Assumed – to be confirmed",R5,0)) -> 9
A6: PILOT – SOURCE DRAFT | B6: HED-01 | C6: Dished End | D6: PV + HE | E6: Heads / Dished Ends | F6: Made in-house | G6: Plate | H6: SA240 S32205 | I6: ID 3000; raw thickness 12; formed thickness 10 min; 2:1 semi-ellipsoidal; ICR 2700; IKR 510; straight face 50; blank dia 3772 | J6: Dished head (to be defined) | K6: A, B | L6: No | M6: Assumed – to be confirmed | N6: Precise Engineers | O6: Pending – Production Head | P6: Draft | Q6: SP40-02-03-04-001 Rev.0: left/right cold-formed heads; full DP both sides with TPI; template profile check. Variant B added from drawing. PV drawing item 102: two SA516 Gr.70 dished ends, 45T nominal × 2925 blank dia; 4748 kg total. | R6: =IF(B6="","",COUNTIF('Part Routes'!$B:$B,B6)) -> 16 | S6: =IF(B6="","",IF(D6="PV",COUNTIFS('Part Routes'!$B:$B,B6,'Part Routes'!$I:$I,""),IF(D6="HE",COUNTIFS('Part Routes'!$B:$B,B6,'Part Routes'!$J:$J,""),COUNTIFS('Part Routes'!$B:$B,B6,'Part Routes'!$I:$I,"")+COUNTIFS('Part Routes'!$B:$B,B6,'Part Routes'!$J:$J,"")))) -> 0 | T6: =IF(B6="","",IF(M6="Assumed – to be confirmed",R6,0)) -> 16
A7: PILOT – SOURCE DRAFT | B7: NOZ-01 | C7: Nozzle Neck | D7: PV + HE | E7: Nozzles | F7: Made in-house | G7: Pipe | H7: SA790 S32205 | I7: OD, thickness, cut length, NB/tag, projection; drawing range includes OD 21.3 to 813 | J7: Pipe / Tube (OD, T, L) | K7: A | L7: No | M7: Assumed – to be confirmed | N7: Precise Engineers | O7: Pending – Production Head | P7: Draft | Q7: SP40 overall material list confirms pipe-neck nozzle construction in SA790 S32205; fabrication route still requires shop approval. PV items 207, 209 and 236 add SA333 Gr.6 and SA106 Gr.B nozzle-neck variants. | R7: =IF(B7="","",COUNTIF('Part Routes'!$B:$B,B7)) -> 9 | S7: =IF(B7="","",IF(D7="PV",COUNTIFS('Part Routes'!$B:$B,B7,'Part Routes'!$I:$I,""),IF(D7="HE",COUNTIFS('Part Routes'!$B:$B,B7,'Part Routes'!$J:$J,""),COUNTIFS('Part Routes'!$B:$B,B7,'Part Routes'!$I:$I,"")+COUNTIFS('Part Routes'!$B:$B,B7,'Part Routes'!$J:$J,"")))) -> 0 | T7: =IF(B7="","",IF(M7="Assumed – to be confirmed",R7,0)) -> 9
A8: PILOT – SOURCE DRAFT | B8: FLG-01 | C8: Nozzle Flange | D8: PV + HE | E8: Flanges | F8: Bought + machined in-house | G8: Forging | H8: SA182 Gr.F60 | I8: NB, class, SORF type, facing, bore, OD, ID, thickness | J8: Ring / Flange (OD, ID, T) | K8: A | L8: No | M8: Assumed – to be confirmed | N8: Precise Engineers | O8: Pending – Production Head | P8: Draft | Q8: SP40 overall material list shows SORF flanges, Class 150, SA182 Gr.F60. Make/buy and machining route remain to be confirmed. PV items 205, 206, 213 and 216 add SA105 Class 300 WNRF variants. | R8: =IF(B8="","",COUNTIF('Part Routes'!$B:$B,B8)) -> 5 | S8: =IF(B8="","",IF(D8="PV",COUNTIFS('Part Routes'!$B:$B,B8,'Part Routes'!$I:$I,""),IF(D8="HE",COUNTIFS('Part Routes'!$B:$B,B8,'Part Routes'!$J:$J,""),COUNTIFS('Part Routes'!$B:$B,B8,'Part Routes'!$I:$I,"")+COUNTIFS('Part Routes'!$B:$B,B8,'Part Routes'!$J:$J,"")))) -> 0 | T8: =IF(B8="","",IF(M8="Assumed – to be confirmed",R8,0)) -> 5
A9: PILOT – SOURCE DRAFT | B9: TSH-01 | C9: Tube Sheet | D9: HE | E9: Tube Bundle | F9: Bought + machined in-house | G9: Forging | H9: SA 266 Gr.2 / SA 182 / SB 171 Alloy 464 | I9: OD, thickness, hole count, hole diameter, pitch, layout, pass partition grooves | J9: Disc (OD, T) | K9: A | L9: No | M9: Assumed – to be confirmed | N9: Precise Engineers | O9: Pending – Production Head | P9: Draft | Q9: Existing forged tubesheet family retained. SP40 uses a separate fabricated-plate family TSH-02. | R9: =IF(B9="","",COUNTIF('Part Routes'!$B:$B,B9)) -> 7 | S9: =IF(B9="","",IF(D9="PV",COUNTIFS('Part Routes'!$B:$B,B9,'Part Routes'!$I:$I,""),IF(D9="HE",COUNTIFS('Part Routes'!$B:$B,B9,'Part Routes'!$J:$J,""),COUNTIFS('Part Routes'!$B:$B,B9,'Part Routes'!$I:$I,"")+COUNTIFS('Part Routes'!$B:$B,B9,'Part Routes'!$J:$J,"")))) -> 0 | T9: =IF(B9="","",IF(M9="Assumed – to be confirmed",R9,0)) -> 7
A10: PILOT – SOURCE DRAFT | B10: TUB-01 | C10: Tube | D10: HE | E10: Tube Bundle | F10: Bought-out | G10: Tube | H10: SB338 Gr.2 titanium / other approved tube materials | I10: OD, wall thickness, effective length, overall length, quantity; SP40: OD 21.3 × 0.4, 3000 overall (Effects 1–8), 2260 overall (Effect 9) | J10: Pipe / Tube (OD, T, L) | K10: A | L10: Yes | M10: Assumed – to be confirmed | N10: Precise Engineers | O10: Pending – Production Head | P10: Draft | Q10: SP40-02-02-11-04 Rev.0 specifies tubes tight-fit with EPDM grommets; no expansion, seal weld or joint test is stated. | R10: =IF(B10="","",COUNTIF('Part Routes'!$B:$B,B10)) -> 5 | S10: =IF(B10="","",IF(D10="PV",COUNTIFS('Part Routes'!$B:$B,B10,'Part Routes'!$I:$I,""),IF(D10="HE",COUNTIFS('Part Routes'!$B:$B,B10,'Part Routes'!$J:$J,""),COUNTIFS('Part Routes'!$B:$B,B10,'Part Routes'!$I:$I,"")+COUNTIFS('Part Routes'!$B:$B,B10,'Part Routes'!$J:$J,"")))) -> 0 | T10: =IF(B10="","",IF(M10="Assumed – to be confirmed",R10,0)) -> 5
A11: PILOT – SOURCE DRAFT | B11: BAF-01 | C11: Baffle | D11: HE | E11: Tube Bundle | F11: Made in-house | G11: Plate | H11: SA 515 Gr.60 / CS / SS | I11: OD, thickness, baffle cut %, hole count, hole diameter, pitch, orientation | J11: Disc (OD, T) | K11: A | L11: No | M11: Assumed – to be confirmed | N11: Precise Engineers | O11: Pending – Production Head | P11: Draft | Q11: Existing generic baffle retained. SP40 drawing package separately defines an EPDM baffle-grommet family. | R11: =IF(B11="","",COUNTIF('Part Routes'!$B:$B,B11)) -> 6 | S11: =IF(B11="","",IF(D11="PV",COUNTIFS('Part Routes'!$B:$B,B11,'Part Routes'!$I:$I,""),IF(D11="HE",COUNTIFS('Part Routes'!$B:$B,B11,'Part Routes'!$J:$J,""),COUNTIFS('Part Routes'!$B:$B,B11,'Part Routes'!$I:$I,"")+COUNTIFS('Part Routes'!$B:$B,B11,'Part Routes'!$J:$J,"")))) -> 0 | T11: =IF(B11="","",IF(M11="Assumed – to be confirmed",R11,0)) -> 6
A12: PILOT – SOURCE DRAFT | B12: SAD-01 | C12: Saddle | D12: PV + HE | E12: Externals / Supports | F12: Made in-house | G12: Assembly (made of other parts) | H12: Metal structure per saddle drawing; PTFE sliding sheet | I12: vessel OD; saddle steel-part dimensions; fixed/sliding type; PTFE sheet 10 × 450 × 3030 | J12: Sum of child parts | K12: A | L12: No | M12: Assumed – to be confirmed | N12: Precise Engineers | O12: Pending – Production Head | P12: Draft | Q12: SP40-02-02-11-01 Rev.0 confirms saddle assembly and food-grade PTFE sliding sheet; metal material/route requires review. | R12: =IF(B12="","",COUNTIF('Part Routes'!$B:$B,B12)) -> 10 | S12: =IF(B12="","",IF(D12="PV",COUNTIFS('Part Routes'!$B:$B,B12,'Part Routes'!$I:$I,""),IF(D12="HE",COUNTIFS('Part Routes'!$B:$B,B12,'Part Routes'!$J:$J,""),COUNTIFS('Part Routes'!$B:$B,B12,'Part Routes'!$I:$I,"")+COUNTIFS('Part Routes'!$B:$B,B12,'Part Routes'!$J:$J,"")))) -> 0 | T12: =IF(B12="","",IF(M12="Assumed – to be confirmed",R12,0)) -> 10
A13: PILOT – SOURCE DRAFT | B13: STD-01 | C13: Stud with Two Nuts | D13: PV + HE | E13: Bolting & Gaskets | F13: Bought-out | G13: Standard item (catalogue) | H13: SA193 Gr.B8M stud with SA194 Gr.8M nuts | I13: diameter, thread, length, quantity; SP40 examples 1/2 in × 75/80 and 5/8 in × 100 | J13: Catalogue weight (per piece) | K13: A | L13: Yes | M13: Assumed – to be confirmed | N13: Precise Engineers | O13: Pending – Production Head | P13: Draft | Q13: SP40 overall material list confirms B8M studs, Gr.8M nuts and separate SS316L washers. PV item 220: 24 sets SA193 B7 studs / SA194 2H heavy hex nuts, 1-1/4 UNC × 210. | R13: =IF(B13="","",COUNTIF('Part Routes'!$B:$B,B13)) -> 3 | S13: =IF(B13="","",IF(D13="PV",COUNTIFS('Part Routes'!$B:$B,B13,'Part Routes'!$I:$I,""),IF(D13="HE",COUNTIFS('Part Routes'!$B:$B,B13,'Part Routes'!$J:$J,""),COUNTIFS('Part Routes'!$B:$B,B13,'Part Routes'!$I:$I,"")+COUNTIFS('Part Routes'!$B:$B,B13,'Part Routes'!$J:$J,"")))) -> 0 | T13: =IF(B13="","",IF(M13="Assumed – to be confirmed",R13,0)) -> 3
A14: PILOT – SOURCE DRAFT | B14: GAS-01 | C14: Gasket | D14: PV + HE | E14: Bolting & Gaskets | F14: Bought-out | G14: Standard item (catalogue) | H14: EPDM food grade / other approved gasket grade | I14: OD, ID, thickness, class/construction, quantity; SP40 examples 3 THK, OD/ID 48/21, 67/33 and 105/60 | J14: Catalogue weight (per piece) | K14: A | L14: Yes | M14: Assumed – to be confirmed | N14: Precise Engineers | O14: Pending – Production Head | P14: Draft | Q14: SP40 overall material list specifies EPDM gaskets. Density and exact compound remain vendor-certificate dependent. PV item 219: DN450 Class 300 SS316L spiral-wound Grafoil gasket with CS outer ring. | R14: =IF(B14="","",COUNTIF('Part Routes'!$B:$B,B14)) -> 3 | S14: =IF(B14="","",IF(D14="PV",COUNTIFS('Part Routes'!$B:$B,B14,'Part Routes'!$I:$I,""),IF(D14="HE",COUNTIFS('Part Routes'!$B:$B,B14,'Part Routes'!$J:$J,""),COUNTIFS('Part Routes'!$B:$B,B14,'Part Routes'!$I:$I,"")+COUNTIFS('Part Routes'!$B:$B,B14,'Part Routes'!$J:$J,"")))) -> 0 | T14: =IF(B14="","",IF(M14="Assumed – to be confirmed",R14,0)) -> 3
A15: DRAWING SOURCE DRAFT | B15: RFP-01 | C15: Reinforcement Pad | D15: HE | E15: Nozzles | F15: Made in-house | G15: Plate | H15: SA240 S32205 | I15: OD, ID, thickness, quantity | J15: Ring / Flange (OD, ID, T) | K15: A | L15: No | M15: Client / QAP requirement | P15: Draft | Q15: SP40 drawing BOM includes nozzle and piping-support reinforcement pads; manufacturing route not stated. | R15: =IF(B15="","",COUNTIF('Part Routes'!$B:$B,B15)) -> 0 | S15: =IF(B15="","",IF(D15="PV",COUNTIFS('Part Routes'!$B:$B,B15,'Part Routes'!$I:$I,""),IF(D15="HE",COUNTIFS('Part Routes'!$B:$B,B15,'Part Routes'!$J:$J,""),COUNTIFS('Part Routes'!$B:$B,B15,'Part Routes'!$I:$I,"")+COUNTIFS('Part Routes'!$B:$B,B15,'Part Routes'!$J:$J,"")))) -> 0 | T15: =IF(B15="","",IF(M15="Assumed – to be confirmed",R15,0)) -> 0
A16: DRAWING SOURCE DRAFT | B16: TSH-02 | C16: Tube Sheet (Fabricated Plate) | D16: HE | E16: Tube Bundle | F16: Made in-house | G16: Plate | H16: SA240 S32205 | I16: OD, thickness, plate joints, hole count/layout, hole dia, pitch, chamfer, finish | J16: Disc (OD, T) | K16: A | L16: No | M16: Client / QAP requirement | P16: Draft | Q16: SP40-02-03-04-002 Rev.0: OD 3000 × 10; hole Ø24.7; 28.78 pitch; 1.6 micron finish; six effect-specific layouts. | R16: =IF(B16="","",COUNTIF('Part Routes'!$B:$B,B16)) -> 7 | S16: =IF(B16="","",IF(D16="PV",COUNTIFS('Part Routes'!$B:$B,B16,'Part Routes'!$I:$I,""),IF(D16="HE",COUNTIFS('Part Routes'!$B:$B,B16,'Part Routes'!$J:$J,""),COUNTIFS('Part Routes'!$B:$B,B16,'Part Routes'!$I:$I,"")+COUNTIFS('Part Routes'!$B:$B,B16,'Part Routes'!$J:$J,"")))) -> 7 | T16: =IF(B16="","",IF(M16="Assumed – to be confirmed",R16,0)) -> 0
A17: DRAWING SOURCE DRAFT | B17: NUT-01 | C17: Hex Nut | D17: HE | E17: Bolting & Gaskets | F17: Bought-out | G17: Standard item (catalogue) | H17: SA194 Gr.8M | I17: thread diameter, grade, quantity | J17: Catalogue weight (per piece) | K17: A | L17: Yes | M17: Client / QAP requirement | P17: Draft | Q17: Listed separately in SP40 nozzle BOM. | R17: =IF(B17="","",COUNTIF('Part Routes'!$B:$B,B17)) -> 0 | S17: =IF(B17="","",IF(D17="PV",COUNTIFS('Part Routes'!$B:$B,B17,'Part Routes'!$I:$I,""),IF(D17="HE",COUNTIFS('Part Routes'!$B:$B,B17,'Part Routes'!$J:$J,""),COUNTIFS('Part Routes'!$B:$B,B17,'Part Routes'!$I:$I,"")+COUNTIFS('Part Routes'!$B:$B,B17,'Part Routes'!$J:$J,"")))) -> 0 | T17: =IF(B17="","",IF(M17="Assumed – to be confirmed",R17,0)) -> 0
A18: DRAWING SOURCE DRAFT | B18: WSH-01 | C18: Washer | D18: HE | E18: Bolting & Gaskets | F18: Bought-out | G18: Standard item (catalogue) | H18: SS316L | I18: nominal diameter, OD, ID, thickness, quantity | J18: Catalogue weight (per piece) | K18: A | L18: Yes | M18: Client / QAP requirement | P18: Draft | Q18: Listed separately in SP40 nozzle BOM. | R18: =IF(B18="","",COUNTIF('Part Routes'!$B:$B,B18)) -> 0 | S18: =IF(B18="","",IF(D18="PV",COUNTIFS('Part Routes'!$B:$B,B18,'Part Routes'!$I:$I,""),IF(D18="HE",COUNTIFS('Part Routes'!$B:$B,B18,'Part Routes'!$J:$J,""),COUNTIFS('Part Routes'!$B:$B,B18,'Part Routes'!$I:$I,"")+COUNTIFS('Part Routes'!$B:$B,B18,'Part Routes'!$J:$J,"")))) -> 0 | T18: =IF(B18="","",IF(M18="Assumed – to be confirmed",R18,0)) -> 0
A19: DRAWING SOURCE DRAFT | B19: GRM-01 | C19: Tube Grommet | D19: HE | E19: Tube Bundle | F19: Bought-out | G19: Standard item (catalogue) | H19: EPDM food grade | I19: tube OD, tubesheet hole, profile dimensions, Shore hardness, quantity | J19: Catalogue weight (per piece) | K19: A | L19: Yes | M19: Client / QAP requirement | P19: Draft | Q19: SP40-02-02-11-04/-05 Rev.0: tube is tight-fit with grommet; no expansion or seal weld stated. | R19: =IF(B19="","",COUNTIF('Part Routes'!$B:$B,B19)) -> 0 | S19: =IF(B19="","",IF(D19="PV",COUNTIFS('Part Routes'!$B:$B,B19,'Part Routes'!$I:$I,""),IF(D19="HE",COUNTIFS('Part Routes'!$B:$B,B19,'Part Routes'!$J:$J,""),COUNTIFS('Part Routes'!$B:$B,B19,'Part Routes'!$I:$I,"")+COUNTIFS('Part Routes'!$B:$B,B19,'Part Routes'!$J:$J,"")))) -> 0 | T19: =IF(B19="","",IF(M19="Assumed – to be confirmed",R19,0)) -> 0
A20: DRAWING SOURCE DRAFT | B20: BGM-01 | C20: Baffle Grommet | D20: HE | E20: Tube Bundle | F20: Bought-out | G20: Standard item (catalogue) | H20: EPDM food grade | I20: tube OD, baffle hole, profile dimensions, Shore hardness, quantity | J20: Catalogue weight (per piece) | K20: A | L20: Yes | M20: Client / QAP requirement | P20: Draft | Q20: SP40-02-02-11-07 Rev.0 requires food-grade EPDM certificate and Shore hardness. | R20: =IF(B20="","",COUNTIF('Part Routes'!$B:$B,B20)) -> 0 | S20: =IF(B20="","",IF(D20="PV",COUNTIFS('Part Routes'!$B:$B,B20,'Part Routes'!$I:$I,""),IF(D20="HE",COUNTIFS('Part Routes'!$B:$B,B20,'Part Routes'!$J:$J,""),COUNTIFS('Part Routes'!$B:$B,B20,'Part Routes'!$I:$I,"")+COUNTIFS('Part Routes'!$B:$B,B20,'Part Routes'!$J:$J,"")))) -> 0 | T20: =IF(B20="","",IF(M20="Assumed – to be confirmed",R20,0)) -> 0
A21: DRAWING SOURCE DRAFT | B21: PTF-01 | C21: PTFE Sliding Sheet | D21: HE | E21: Externals / Supports | F21: Bought + fabricated in-house | G21: Plate | H21: PTFE food grade | I21: thickness, width, length, hole pattern, quantity | J21: Plate (L x W x T) | K21: A | L21: No | M21: Client / QAP requirement | P21: Draft | Q21: SP40 saddle detail: 10 THK × 450 × 3030; food-grade material. | R21: =IF(B21="","",COUNTIF('Part Routes'!$B:$B,B21)) -> 0 | S21: =IF(B21="","",IF(D21="PV",COUNTIFS('Part Routes'!$B:$B,B21,'Part Routes'!$I:$I,""),IF(D21="HE",COUNTIFS('Part Routes'!$B:$B,B21,'Part Routes'!$J:$J,""),COUNTIFS('Part Routes'!$B:$B,B21,'Part Routes'!$I:$I,"")+COUNTIFS('Part Routes'!$B:$B,B21,'Part Routes'!$J:$J,"")))) -> 0 | T21: =IF(B21="","",IF(M21="Assumed – to be confirmed",R21,0)) -> 0
A22: DRAWING SOURCE DRAFT | B22: MNH-01 | C22: Manhole Assembly | D22: HE | E22: Nozzles | F22: Bought + fabricated in-house | G22: Assembly (made of other parts) | H22: Per approved manhole drawing | I22: ID/NB, neck, cover, flange, bolting, gasket, quantity | J22: Sum of child parts | K22: A | L22: No | M22: Client / QAP requirement | P22: Draft | Q22: SP40 overall material list references four ID590 manholes to SP40-02-02-11-02. | R22: =IF(B22="","",COUNTIF('Part Routes'!$B:$B,B22)) -> 0 | S22: =IF(B22="","",IF(D22="PV",COUNTIFS('Part Routes'!$B:$B,B22,'Part Routes'!$I:$I,""),IF(D22="HE",COUNTIFS('Part Routes'!$B:$B,B22,'Part Routes'!$J:$J,""),COUNTIFS('Part Routes'!$B:$B,B22,'Part Routes'!$I:$I,"")+COUNTIFS('Part Routes'!$B:$B,B22,'Part Routes'!$J:$J,"")))) -> 0 | T22: =IF(B22="","",IF(M22="Assumed – to be confirmed",R22,0)) -> 0
A23: DRAWING SOURCE DRAFT | B23: HNH-01 | C23: Handhole Assembly | D23: HE | E23: Nozzles | F23: Bought + fabricated in-house | G23: Assembly (made of other parts) | H23: Per approved handhole drawing | I23: NB, neck, cover, flange, bolting, gasket, quantity | J23: Sum of child parts | K23: A | L23: No | M23: Client / QAP requirement | P23: Draft | Q23: SP40 overall material list references one NB300 handhole. | R23: =IF(B23="","",COUNTIF('Part Routes'!$B:$B,B23)) -> 0 | S23: =IF(B23="","",IF(D23="PV",COUNTIFS('Part Routes'!$B:$B,B23,'Part Routes'!$I:$I,""),IF(D23="HE",COUNTIFS('Part Routes'!$B:$B,B23,'Part Routes'!$J:$J,""),COUNTIFS('Part Routes'!$B:$B,B23,'Part Routes'!$I:$I,"")+COUNTIFS('Part Routes'!$B:$B,B23,'Part Routes'!$J:$J,"")))) -> 0 | T23: =IF(B23="","",IF(M23="Assumed – to be confirmed",R23,0)) -> 0
A24: DRAWING SOURCE DRAFT | B24: VGL-01 | C24: View Glass | D24: HE | E24: Nozzles | F24: Bought-out | G24: Standard item (catalogue) | H24: Toughened borosilicate | I24: diameter, thickness, rating, quantity | J24: Catalogue weight (per piece) | K24: A | L24: Yes | M24: Client / QAP requirement | P24: Draft | Q24: SP40-02-02-11-03 Rev.0; three view-glass assemblies in overall material list. | R24: =IF(B24="","",COUNTIF('Part Routes'!$B:$B,B24)) -> 0 | S24: =IF(B24="","",IF(D24="PV",COUNTIFS('Part Routes'!$B:$B,B24,'Part Routes'!$I:$I,""),IF(D24="HE",COUNTIFS('Part Routes'!$B:$B,B24,'Part Routes'!$J:$J,""),COUNTIFS('Part Routes'!$B:$B,B24,'Part Routes'!$I:$I,"")+COUNTIFS('Part Routes'!$B:$B,B24,'Part Routes'!$J:$J,"")))) -> 0 | T24: =IF(B24="","",IF(M24="Assumed – to be confirmed",R24,0)) -> 0
A25: DRAWING SOURCE DRAFT | B25: NCG-01 | C25: NCG Box Assembly | D25: HE | E25: Internals | F25: Made in-house | G25: Assembly (made of other parts) | H25: SA240 S32205 | I25: effect/location, plate dimensions, tube-sheet interface, quantity | J25: Sum of child parts | K25: A | L25: No | M25: Client / QAP requirement | P25: Draft | Q25: SP40-02-03-04-006 Rev.0 defines Effect 1.1, 2.1 and 3.1 NCG boxes. | R25: =IF(B25="","",COUNTIF('Part Routes'!$B:$B,B25)) -> 0 | S25: =IF(B25="","",IF(D25="PV",COUNTIFS('Part Routes'!$B:$B,B25,'Part Routes'!$I:$I,""),IF(D25="HE",COUNTIFS('Part Routes'!$B:$B,B25,'Part Routes'!$J:$J,""),COUNTIFS('Part Routes'!$B:$B,B25,'Part Routes'!$I:$I,"")+COUNTIFS('Part Routes'!$B:$B,B25,'Part Routes'!$J:$J,"")))) -> 0 | T25: =IF(B25="","",IF(M25="Assumed – to be confirmed",R25,0)) -> 0
A26: DRAWING SOURCE DRAFT | B26: JTB-01 | C26: J Tube | D26: HE | E26: Internals | F26: Made in-house | G26: Pipe | H26: SA790 S32205 | I26: OD, thickness, developed/cut length, bend geometry, quantity | J26: Pipe / Tube (OD, T, L) | K26: A | L26: No | M26: Client / QAP requirement | P26: Draft | Q26: SP40-02-03-04-007 Rev.0 NCG nozzle and J-tube details. | R26: =IF(B26="","",COUNTIF('Part Routes'!$B:$B,B26)) -> 0 | S26: =IF(B26="","",IF(D26="PV",COUNTIFS('Part Routes'!$B:$B,B26,'Part Routes'!$I:$I,""),IF(D26="HE",COUNTIFS('Part Routes'!$B:$B,B26,'Part Routes'!$J:$J,""),COUNTIFS('Part Routes'!$B:$B,B26,'Part Routes'!$I:$I,"")+COUNTIFS('Part Routes'!$B:$B,B26,'Part Routes'!$J:$J,"")))) -> 0 | T26: =IF(B26="","",IF(M26="Assumed – to be confirmed",R26,0)) -> 0
... A34: DRAWING SOURCE DRAFT | B34: SUP-01 | C34: Support Plate | D34: HE | E34: Internals | F34: Made in-house | G34: Plate | H34: SA240 S32205 | I34: profile, thickness, quantity | J34: Plate (L x W x T) | K34: A | L34: No | M34: Client / QAP requirement | P34: Draft | Q34: Support plates shown in SP40 demister/internal details; route not stated. | R34: =IF(B34="","",COUNTIF('Part Routes'!$B:$B,B34)) -> 0 | S34: =IF(B34="","",IF(D34="PV",COUNTIFS('Part Routes'!$B:$B,B34,'Part Routes'!$I:$I,""),IF(D34="HE",COUNTIFS('Part Routes'!$B:$B,B34,'Part Routes'!$J:$J,""),COUNTIFS('Part Routes'!$B:$B,B34,'Part Routes'!$I:$I,"")+COUNTIFS('Part Routes'!$B:$B,B34,'Part Routes'!$J:$J,"")))) -> 0 | T34: =IF(B34="","",IF(M34="Assumed – to be confirmed",R34,0)) -> 0
A35: PV DRAWING SOURCE | B35: SKT-01 | C35: Skirt Shell | D35: PV | E35: Externals / Supports | F35: Made in-house | G35: Plate | H35: SA 516 Gr.70 | I35: Thickness, width, developed length, vessel/skirt diameter | J35: Rolled shell (ID, T, L) | K35: A | L35: No | M35: Assumed – to be confirmed | N35: Precise Engineers | O35: Pending – Production Head | P35: Draft | Q35: Drawing item 201; 16T × 837W × 7499 developed length; 789 kg | R35: =COUNTIF('Part Routes'!$B:$B,B35) -> 9 | S35: =COUNTIFS('Part Routes'!$B:$B,B35,'Part Routes'!$I:$I,"") -> 0 | T35: =COUNTIFS('Part Routes'!$B:$B,B35,'Part Routes'!$R:$R,"*PROPOSED*") -> 9
A36: PV DRAWING SOURCE | B36: SBR-01 | C36: Skirt Base Ring | D36: PV | E36: Externals / Supports | F36: Made in-house | G36: Plate | H36: IS 2062 E250B | I36: Thickness, ID, OD, bolt-hole count/PCD | J36: Ring / Flange (OD, ID, T) | K36: A | L36: No | M36: Assumed – to be confirmed | N36: Precise Engineers | O36: Pending – Production Head | P36: Draft | Q36: Drawing item 202; 32T × 2240 ID × 2700 OD; 448 kg | R36: =COUNTIF('Part Routes'!$B:$B,B36) -> 6 | S36: =COUNTIFS('Part Routes'!$B:$B,B36,'Part Routes'!$I:$I,"") -> 0 | T36: =COUNTIFS('Part Routes'!$B:$B,B36,'Part Routes'!$R:$R,"*PROPOSED*") -> 6
A37: PV DRAWING SOURCE | B37: GSP-02 | C37: Gusset Plate (PV Support) | D37: PV | E37: Externals / Supports | F37: Made in-house | G37: Plate | H37: IS 2062 E250B | I37: Thickness, width, length, profile, quantity | J37: Plate (L x W x T) | K37: A | L37: No | M37: Assumed – to be confirmed | N37: Precise Engineers | O37: Pending – Production Head | P37: Draft | Q37: Drawing item 203; qty 32; 12T × 150W × 151 length | R37: =COUNTIF('Part Routes'!$B:$B,B37) -> 6 | S37: =COUNTIFS('Part Routes'!$B:$B,B37,'Part Routes'!$I:$I,"") -> 0 | T37: =COUNTIFS('Part Routes'!$B:$B,B37,'Part Routes'!$R:$R,"*PROPOSED*") -> 6
A38: PV DRAWING SOURCE | B38: ERT-01 | C38: Earthing Plate | D38: PV | E38: Externals / Supports | F38: Made in-house | G38: Plate | H38: SS 304 | I38: Thickness, width, length, hole size/count | J38: Plate (L x W x T) | K38: A | L38: No | M38: Assumed – to be confirmed | N38: Precise Engineers | O38: Pending – Production Head | P38: Draft | Q38: Drawing item 204; qty 2; detail requires four holes | R38: =COUNTIF('Part Routes'!$B:$B,B38) -> 6 | S38: =COUNTIFS('Part Routes'!$B:$B,B38,'Part Routes'!$I:$I,"") -> 0 | T38: =COUNTIFS('Part Routes'!$B:$B,B38,'Part Routes'!$R:$R,"*PROPOSED*") -> 6
A39: PV DRAWING SOURCE | B39: RFP-02 | C39: Nozzle Reinforcement Pad | D39: PV | E39: Nozzles | F39: Made in-house | G39: Plate | H39: SA 516 Gr.70 | I39: Thickness, OD, ID, vent-hole size, curvature | J39: Ring / Flange (OD, ID, T) | K39: A | L39: No | M39: Assumed – to be confirmed | N39: Precise Engineers | O39: Pending – Production Head | P39: Draft | Q39: Drawing item 205A; final dimension unclear in source crop | R39: =COUNTIF('Part Routes'!$B:$B,B39) -> 6 | S39: =COUNTIFS('Part Routes'!$B:$B,B39,'Part Routes'!$I:$I,"") -> 0 | T39: =COUNTIFS('Part Routes'!$B:$B,B39,'Part Routes'!$R:$R,"*PROPOSED*") -> 6
A40: PV DRAWING SOURCE | B40: ELB-01 | C40: Nozzle Elbow | D40: PV | E40: Nozzles | F40: Bought-out | G40: Pipe fitting | H40: SA 234 WPB | I40: DN/NPS, schedule, angle, radius | J40: Catalogue weight (per piece) | K40: A | L40: No | M40: Assumed – to be confirmed | N40: Precise Engineers | O40: Pending – Production Head | P40: Draft | Q40: Drawing item 208; DN25 Sch XXS 90° LR | R40: =COUNTIF('Part Routes'!$B:$B,B40) -> 3 | S40: =COUNTIFS('Part Routes'!$B:$B,B40,'Part Routes'!$I:$I,"") -> 0 | T40: =COUNTIFS('Part Routes'!$B:$B,B40,'Part Routes'!$R:$R,"*PROPOSED*") -> 3
A41: PV DRAWING SOURCE | B41: STF-01 | C41: Nozzle Stiffener | D41: PV | E41: Nozzles | F41: Made in-house | G41: Plate | H41: SA 516 Gr.70 | I41: Thickness, width, length, profile, quantity | J41: Plate (L x W x T) | K41: A | L41: No | M41: Assumed – to be confirmed | N41: Precise Engineers | O41: Pending – Production Head | P41: Draft | Q41: Drawing items 210 and 212; item 210 weight unclear | R41: =COUNTIF('Part Routes'!$B:$B,B41) -> 6 | S41: =COUNTIFS('Part Routes'!$B:$B,B41,'Part Routes'!$I:$I,"") -> 0 | T41: =COUNTIFS('Part Routes'!$B:$B,B41,'Part Routes'!$R:$R,"*PROPOSED*") -> 6
A42: PV DRAWING SOURCE | B42: SRN-01 | C42: Self-Reinforced Nozzle | D42: PV | E42: Nozzles | F42: Bought + machined in-house | G42: Forging | H42: SA 266 Gr.2 | I42: Tag, OD/ID, neck length, flange interface, contour | J42: Catalogue weight (per piece) | K42: A | L42: No | M42: Assumed – to be confirmed | N42: Precise Engineers | O42: Pending – Production Head | P42: Draft | Q42: Drawing items 214 and 217; machine as detailed | R42: =COUNTIF('Part Routes'!$B:$B,B42) -> 4 | S42: =COUNTIFS('Part Routes'!$B:$B,B42,'Part Routes'!$I:$I,"") -> 0 | T42: =COUNTIFS('Part Routes'!$B:$B,B42,'Part Routes'!$R:$R,"*PROPOSED*") -> 4
A43: PV DRAWING SOURCE | B43: CPL-01 | C43: Coupling with Plug | D43: PV | E43: Nozzles | F43: Bought + machined in-house | G43: Forging | H43: SA 105 | I43: DN/NPS, pressure rating, thread, projection | J43: Catalogue weight (per piece) | K43: A | L43: No | M43: Assumed – to be confirmed | N43: Precise Engineers | O43: Pending – Production Head | P43: Draft | Q43: Drawing items 215 and 244; DN15 6000# BSP | R43: =COUNTIF('Part Routes'!$B:$B,B43) -> 4 | S43: =COUNTIFS('Part Routes'!$B:$B,B43,'Part Routes'!$I:$I,"") -> 0 | T43: =COUNTIFS('Part Routes'!$B:$B,B43,'Part Routes'!$R:$R,"*PROPOSED*") -> 4
A44: PV DRAWING SOURCE | B44: BFL-01 | C44: Blind Flange | D44: PV | E44: Flanges | F44: Bought-out | G44: Forging | H44: SA 105 | I44: DN/NPS, class, facing, thickness, bolting | J44: Catalogue weight (per piece) | K44: A | L44: No | M44: Assumed – to be confirmed | N44: Precise Engineers | O44: Pending – Production Head | P44: Draft | Q44: Drawing item 218; DN450 Class 300 RF; 181 kg | R44: =COUNTIF('Part Routes'!$B:$B,B44) -> 3 | S44: =COUNTIFS('Part Routes'!$B:$B,B44,'Part Routes'!$I:$I,"") -> 0 | T44: =COUNTIFS('Part Routes'!$B:$B,B44,'Part Routes'!$R:$R,"*PROPOSED*") -> 3
A45: PV DRAWING SOURCE | B45: HOK-01 | C45: Square Bar Hook | D45: PV | E45: Externals / Supports | F45: Made in-house | G45: Bar / Rod | H45: SA 516 Gr.70 | I45: Square size, developed length, bend radius | J45: Bar / Rod (Dia, L) | K45: A | L45: No | M45: Assumed – to be confirmed | N45: Precise Engineers | O45: Pending – Production Head | P45: Draft | Q45: Drawing item 221; square 28 × 400 developed length | R45: =COUNTIF('Part Routes'!$B:$B,B45) -> 5 | S45: =COUNTIFS('Part Routes'!$B:$B,B45,'Part Routes'!$I:$I,"") -> 0 | T45: =COUNTIFS('Part Routes'!$B:$B,B45,'Part Routes'!$R:$R,"*PROPOSED*") -> 5
A46: PV DRAWING SOURCE | B46: EYE-01 | C46: Eye Bolt | D46: PV | E46: Externals / Supports | F46: Made in-house | G46: Bar / Rod | H46: IS 2062 E250B | I46: Rod diameter, developed length, eye diameter, thread | J46: Bar / Rod (Dia, L) | K46: A | L46: No | M46: Assumed – to be confirmed | N46: Precise Engineers | O46: Pending – Production Head | P46: Draft | Q46: Drawing item 222; dia 25 × 500 developed length | R46: =COUNTIF('Part Routes'!$B:$B,B46) -> 5 | S46: =COUNTIFS('Part Routes'!$B:$B,B46,'Part Routes'!$I:$I,"") -> 0 | T46: =COUNTIFS('Part Routes'!$B:$B,B46,'Part Routes'!$R:$R,"*PROPOSED*") -> 5
... A64: PV DRAWING SOURCE | B64: FBL-01 | C64: Foundation Bolt with Nut & Washer | D64: PV | E64: Externals / Supports | F64: Bought-out | G64: Standard item (catalogue) | H64: IS 1367 Gr.8.8 | I64: Thread diameter, length, bend/anchor detail, nut/washer standard | J64: Catalogue weight (per piece) | K64: A | L64: No | M64: Assumed – to be confirmed | N64: Precise Engineers | O64: Pending – Production Head | P64: Draft | Q64: Drawing item 243; qty 16; M36 × 580 length | R64: =COUNTIF('Part Routes'!$B:$B,B64) -> 3 | S64: =COUNTIFS('Part Routes'!$B:$B,B64,'Part Routes'!$I:$I,"") -> 0 | T64: =COUNTIFS('Part Routes'!$B:$B,B64,'Part Routes'!$R:$R,"*PROPOSED*") -> 3
R65: =IF(B65="","",COUNTIF('Part Routes'!$B:$B,B65)) | S65: =IF(B65="","",IF(D65="PV",COUNTIFS('Part Routes'!$B:$B,B65,'Part Routes'!$I:$I,""),IF(D65="HE",COUNTIFS('Part Routes'!$B:$B,B65,'Part Routes'!$J:$J,""),COUNTIFS('Part Routes'!$B:$B,B65,'Part Routes'!$I:$I,"")+COUNTIFS('Part Routes'!$B:$B,B65,'Part Routes'!$J:$J,"")))) | T65: =IF(B65="","",IF(M65="Assumed – to be confirmed",R65,0))
...

Sheet Part Routes
A1: HE + PV ROUTES — LIGHT-YELLOW PV ROUTES USE FIXED OPERATIONS AND APPROVED PV STAGE NUMBERS; PROPOSED TIMES REQUIRE SHOP VALIDATION.
A2: One row per step, numbered 10, 20, 30… Use only operations from the dropdown; anything else goes in 'New Operations'. 'Counts toward Stage No.' is the whole-equipment stage this step belongs to (see 'PV Stages (ref)' and 'HE Stages'); fill both columns for parts used in PV and HE. If a part can be made in two ways, repeat its steps as Variant B. Hold points are not needed here; they come from each job's QAP.
A4: Example? | B4: Part Code | C4: Part Name (auto) | D4: Variant | E4: Seq | F4: Operation | G4: What is done in this step | H4: Department | I4: Counts toward PV Stage No. | J4: Counts toward HE Stage No. | K4: Std. Time | L4: Time Unit | M4: Time Basis | N4: Conditional? | O4: When does it apply? | P4: Acceptance Standard | Q4: Record / Document | R4: Remarks
A5: PILOT – SOURCE DRAFT | B5: SHL-01 | C5: =IF(B5="","",IFERROR(INDEX('Parts Master'!$C:$C,MATCH(B5,'Parts Master'!$B:$B,0)),"Part Code not in Parts Master")) -> Shell Course | D5: A | E5: 10 | F5: Receipt | G5: Plate received and GRN prepared | H5: Stores | I5: 10 | J5: 11 | K5: 0.5 | L5: Hours | M5: Per material lot | N5: No | P5: PO/BOM, packing list and visible condition acceptable | Q5: GRN / incoming inspection record | R5: PROPOSED TIME / STAGE — validate by time study and approve before tracker load.
A6: PILOT – SOURCE DRAFT | B6: SHL-01 | C6: =IF(B6="","",IFERROR(INDEX('Parts Master'!$C:$C,MATCH(B6,'Parts Master'!$B:$B,0)),"Part Code not in Parts Master")) -> Shell Course | D6: A | E6: 20 | F6: MTC Verification / Material Identification | G6: MTC reviewed and heat number transferred | H6: Quality Control / QA | I6: 11 | J6: 12 | K6: 0.75 | L6: Hours | M6: Per material lot | N6: No | P6: Material specification, grade, heat/lot and traceability match PO/BOM | Q6: MTC review / PMI / traceability record | R6: PROPOSED TIME / STAGE — validate by time study and approve before tracker load.
A7: PILOT – SOURCE DRAFT | B7: SHL-01 | C7: =IF(B7="","",IFERROR(INDEX('Parts Master'!$C:$C,MATCH(B7,'Parts Master'!$B:$B,0)),"Part Code not in Parts Master")) -> Shell Course | D7: A | E7: 30 | F7: Cutting / Blanking | G7: Plate cut to developed size | H7: Fabrication Prep | I7: 12 | J7: 13 | K7: 0.3 | L7: Hours | M7: Per metre of cut | N7: No | P7: Cut size and identification meet approved drawing/cutting plan | Q7: Cutting report / material traceability | R7: PROPOSED TIME / STAGE — validate by time study and approve before tracker load.
A8: PILOT – SOURCE DRAFT | B8: SHL-01 | C8: =IF(B8="","",IFERROR(INDEX('Parts Master'!$C:$C,MATCH(B8,'Parts Master'!$B:$B,0)),"Part Code not in Parts Master")) -> Shell Course | D8: A | E8: 40 | F8: Edge Preparation / Beveling | G8: Long-seam edges prepared | H8: Fabrication Prep | I8: 12 | J8: 13 | K8: 0.35 | L8: Hours | M8: Per metre of edge | N8: No | P8: Bevel geometry and cleanliness meet drawing/WPS | Q8: Fit-up / bevel inspection report | R8: PROPOSED TIME / STAGE — validate by time study and approve before tracker load.
A9: PILOT – SOURCE DRAFT | B9: SHL-01 | C9: =IF(B9="","",IFERROR(INDEX('Parts Master'!$C:$C,MATCH(B9,'Parts Master'!$B:$B,0)),"Part Code not in Parts Master")) -> Shell Course | D9: A | E9: 50 | F9: Rolling | G9: Plate rolled to specified diameter | H9: Fabrication Prep | I9: 13 | J9: 14 | K9: 4 | L9: Hours | M9: Per piece | N9: No | P9: Diameter, roundness and straightness within approved drawing tolerance | Q9: Dimensional inspection report | R9: PROPOSED TIME / STAGE — validate by time study and approve before tracker load.
A10: PILOT – SOURCE DRAFT | B10: SHL-01 | C10: =IF(B10="","",IFERROR(INDEX('Parts Master'!$C:$C,MATCH(B10,'Parts Master'!$B:$B,0)),"Part Code not in Parts Master")) -> Shell Course | D10: A | E10: 60 | F10: Fit-up | G10: Long seam aligned and fitted | H10: Fabrication / Welding | I10: 19 | J10: 14 | K10: 1.5 | L10: Hours | M10: Per joint | N10: No | P10: Alignment, root gap, offset and orientation meet WPS/drawing | Q10: Fit-up report | R10: PROPOSED TIME / STAGE — validate by time study and approve before tracker load.
A11: PILOT – SOURCE DRAFT | B11: SHL-01 | C11: =IF(B11="","",IFERROR(INDEX('Parts Master'!$C:$C,MATCH(B11,'Parts Master'!$B:$B,0)),"Part Code not in Parts Master")) -> Shell Course | D11: A | E11: 70 | F11: Welding | G11: Long seam welded to approved WPS | H11: Fabrication / Welding | I11: 20 | J11: 15 | K11: 1.2 | L11: Hours | M11: Per metre of weld | N11: No | P11: Weld completed to approved WPS by qualified welder; visual acceptable | Q11: Weld log / WPS / WPQ | R11: PROPOSED TIME / STAGE — validate by time study and approve before tracker load.
A12: PILOT – SOURCE DRAFT | B12: SHL-01 | C12: =IF(B12="","",IFERROR(INDEX('Parts Master'!$C:$C,MATCH(B12,'Parts Master'!$B:$B,0)),"Part Code not in Parts Master")) -> Shell Course | D12: A | E12: 80 | F12: NDT | G12: Long seam examined by specified NDE | H12: Quality Control / QA | I12: 17 | J12: 16 | K12: 1 | L12: Hours | M12: Per joint | N12: Yes | O12: Extent and method as job QAP | P12: Specified method and extent accepted to applicable code/QAP | Q12: NDE report | R12: PROPOSED TIME / STAGE — validate by time study and approve before tracker load.
A13: PILOT – SOURCE DRAFT | B13: SHL-01 | C13: =IF(B13="","",IFERROR(INDEX('Parts Master'!$C:$C,MATCH(B13,'Parts Master'!$B:$B,0)),"Part Code not in Parts Master")) -> Shell Course | D13: A | E13: 90 | F13: Inspection | G13: Visual and dimensional inspection | H13: Quality Control / QA | I13: 21 | J13: 16 | K13: 0.75 | L13: Hours | M13: Per piece | N13: No | P13: Visual and dimensional results meet approved drawing/QAP | Q13: Dimensional / final inspection report | R13: PROPOSED TIME / STAGE — validate by time study and approve before tracker load.
A14: PILOT – SOURCE DRAFT | B14: HED-01 | C14: =IF(B14="","",IFERROR(INDEX('Parts Master'!$C:$C,MATCH(B14,'Parts Master'!$B:$B,0)),"Part Code not in Parts Master")) -> Dished End | D14: A | E14: 10 | F14: Receipt | G14: Head plate or formed head received | H14: Stores | I14: 10 | J14: 11 | K14: 0.5 | L14: Hours | M14: Per material lot | N14: No | P14: PO/BOM, packing list and visible condition acceptable | Q14: GRN / incoming inspection record | R14: PROPOSED TIME / STAGE — validate by time study and approve before tracker load.
A15: PILOT – SOURCE DRAFT | B15: HED-01 | C15: =IF(B15="","",IFERROR(INDEX('Parts Master'!$C:$C,MATCH(B15,'Parts Master'!$B:$B,0)),"Part Code not in Parts Master")) -> Dished End | D15: A | E15: 20 | F15: MTC Verification / Material Identification | G15: MTC and traceability verified | H15: Quality Control / QA | I15: 11 | J15: 12 | K15: 0.75 | L15: Hours | M15: Per material lot | N15: No | P15: Material specification, grade, heat/lot and traceability match PO/BOM | Q15: MTC review / PMI / traceability record | R15: PROPOSED TIME / STAGE — validate by time study and approve before tracker load.
A16: PILOT – SOURCE DRAFT | B16: HED-01 | C16: =IF(B16="","",IFERROR(INDEX('Parts Master'!$C:$C,MATCH(B16,'Parts Master'!$B:$B,0)),"Part Code not in Parts Master")) -> Dished End | D16: A | E16: 30 | F16: Cutting / Blanking | G16: Blank or petals cut to drawing | H16: Fabrication Prep | I16: 12 | J16: 13 | K16: 0.3 | L16: Hours | M16: Per metre of cut | N16: No | P16: Cut size and identification meet approved drawing/cutting plan | Q16: Cutting report / material traceability | R16: PROPOSED TIME / STAGE — validate by time study and approve before tracker load.
A17: PILOT – SOURCE DRAFT | B17: HED-01 | C17: =IF(B17="","",IFERROR(INDEX('Parts Master'!$C:$C,MATCH(B17,'Parts Master'!$B:$B,0)),"Part Code not in Parts Master")) -> Dished End | D17: A | E17: 40 | F17: Edge Preparation / Beveling | G17: Edges prepared for forming or welding | H17: Fabrication Prep | I17: 12 | J17: 13 | K17: 0.35 | L17: Hours | M17: Per metre of edge | N17: No | P17: Bevel geometry and cleanliness meet drawing/WPS | Q17: Fit-up / bevel inspection report | R17: PROPOSED TIME / STAGE — validate by time study and approve before tracker load.
A18: PILOT – SOURCE DRAFT | B18: HED-01 | C18: =IF(B18="","",IFERROR(INDEX('Parts Master'!$C:$C,MATCH(B18,'Parts Master'!$B:$B,0)),"Part Code not in Parts Master")) -> Dished End | D18: A | E18: 50 | F18: Forming / Pressing / Dishing | G18: Head formed to specified profile | H18: Fabrication Prep | I18: 13 | J18: 17 | K18: 16 | L18: Hours | M18: Per piece | N18: No | P18: Profile, minimum thickness and dimensions meet drawing/code | Q18: Forming and thickness/profile report | R18: PROPOSED TIME / STAGE — validate by time study and approve before tracker load.
A19: PILOT – SOURCE DRAFT | B19: HED-01 | C19: =IF(B19="","",IFERROR(INDEX('Parts Master'!$C:$C,MATCH(B19,'Parts Master'!$B:$B,0)),"Part Code not in Parts Master")) -> Dished End | D19: A | E19: 60 | F19: Grinding | G19: Trim and dress formed edge | H19: Fabrication Prep | I19: 13 | J19: 17 | K19: 0.4 | L19: Hours | M19: Per metre of edge | N19: No | P19: Surface smooth, defect-free and blended without under-thickness | Q19: Visual inspection record | R19: PROPOSED TIME / STAGE — validate by time study and approve before tracker load.
A20: PILOT – SOURCE DRAFT | B20: HED-01 | C20: =IF(B20="","",IFERROR(INDEX('Parts Master'!$C:$C,MATCH(B20,'Parts Master'!$B:$B,0)),"Part Code not in Parts Master")) -> Dished End | D20: A | E20: 70 | F20: Fit-up | G20: Segments or head seam fitted | H20: Fabrication / Welding | I20: 19 | J20: 25 | K20: 1.5 | L20: Hours | M20: Per joint | N20: Yes | O20: Only for segmented or welded construction | P20: Alignment, root gap, offset and orientation meet WPS/drawing | Q20: Fit-up report | R20: PROPOSED TIME / STAGE — validate by time study and approve before tracker load.
A21: PILOT – SOURCE DRAFT | B21: HED-01 | C21: =IF(B21="","",IFERROR(INDEX('Parts Master'!$C:$C,MATCH(B21,'Parts Master'!$B:$B,0)),"Part Code not in Parts Master")) -> Dished End | D21: A | E21: 80 | F21: Welding | G21: Segments or head seam welded | H21: Fabrication / Welding | I21: 20 | J21: 25 | K21: 1.2 | L21: Hours | M21: Per metre of weld | N21: Yes | O21: Only for segmented or welded construction | P21: Weld completed to approved WPS by qualified welder; visual acceptable | Q21: Weld log / WPS / WPQ | R21: PROPOSED TIME / STAGE — validate by time study and approve before tracker load.
A22: PILOT – SOURCE DRAFT | B22: HED-01 | C22: =IF(B22="","",IFERROR(INDEX('Parts Master'!$C:$C,MATCH(B22,'Parts Master'!$B:$B,0)),"Part Code not in Parts Master")) -> Dished End | D22: A | E22: 90 | F22: NDT | G22: Specified examination of welds or formed head | H22: Quality Control / QA | I22: 17 | J22: 17 | K22: 1 | L22: Hours | M22: Per joint | N22: Yes | O22: As required by drawing or QAP | P22: Specified method and extent accepted to applicable code/QAP | Q22: NDE report | R22: PROPOSED TIME / STAGE — validate by time study and approve before tracker load.
A23: PILOT – SOURCE DRAFT | B23: HED-01 | C23: =IF(B23="","",IFERROR(INDEX('Parts Master'!$C:$C,MATCH(B23,'Parts Master'!$B:$B,0)),"Part Code not in Parts Master")) -> Dished End | D23: A | E23: 100 | F23: Inspection | G23: Profile, thickness and dimensions checked | H23: Quality Control / QA | I23: 21 | J23: 17 | K23: 0.75 | L23: Hours | M23: Per piece | N23: No | P23: Visual and dimensional results meet approved drawing/QAP | Q23: Dimensional / final inspection report | R23: PROPOSED TIME / STAGE — validate by time study and approve before tracker load.
A24: PILOT – SOURCE DRAFT | B24: NOZ-01 | C24: =IF(B24="","",IFERROR(INDEX('Parts Master'!$C:$C,MATCH(B24,'Parts Master'!$B:$B,0)),"Part Code not in Parts Master")) -> Nozzle Neck | D24: A | E24: 10 | F24: Receipt | G24: Pipe or neck forging received | H24: Stores | I24: 10 | J24: 11 | K24: 0.5 | L24: Hours | M24: Per material lot | N24: No | P24: PO/BOM, packing list and visible condition acceptable | Q24: GRN / incoming inspection record | R24: PROPOSED TIME / STAGE — validate by time study and approve before tracker load.
A25: PILOT – SOURCE DRAFT | B25: NOZ-01 | C25: =IF(B25="","",IFERROR(INDEX('Parts Master'!$C:$C,MATCH(B25,'Parts Master'!$B:$B,0)),"Part Code not in Parts Master")) -> Nozzle Neck | D25: A | E25: 20 | F25: MTC Verification / Material Identification | G25: MTC and identification verified | H25: Quality Control / QA | I25: 11 | J25: 12 | K25: 0.75 | L25: Hours | M25: Per material lot | N25: No | P25: Material specification, grade, heat/lot and traceability match PO/BOM | Q25: MTC review / PMI / traceability record | R25: PROPOSED TIME / STAGE — validate by time study and approve before tracker load.
A26: PILOT – SOURCE DRAFT | B26: NOZ-01 | C26: =IF(B26="","",IFERROR(INDEX('Parts Master'!$C:$C,MATCH(B26,'Parts Master'!$B:$B,0)),"Part Code not in Parts Master")) -> Nozzle Neck | D26: A | E26: 30 | F26: Cutting / Blanking | G26: Neck cut to job length | H26: Fabrication Prep | I26: 12 | J26: 23 | K26: 0.3 | L26: Hours | M26: Per metre of cut | N26: No | P26: Cut size and identification meet approved drawing/cutting plan | Q26: Cutting report / material traceability | R26: PROPOSED TIME / STAGE — validate by time study and approve before tracker load.
A27: PILOT – SOURCE DRAFT | B27: NOZ-01 | C27: =IF(B27="","",IFERROR(INDEX('Parts Master'!$C:$C,MATCH(B27,'Parts Master'!$B:$B,0)),"Part Code not in Parts Master")) -> Nozzle Neck | D27: A | E27: 40 | F27: Machining | G27: Facing or bore machining completed | H27: Machine Shop | I27: 14 | J27: 23 | K27: 1 | L27: Hours | M27: Per piece | N27: Yes | O27: When drawing requires machining | P27: Dimensions, tolerances and surface finish meet approved drawing | Q27: Machining inspection report | R27: PROPOSED TIME / STAGE — validate by time study and approve before tracker load.
A28: PILOT – SOURCE DRAFT | B28: NOZ-01 | C28: =IF(B28="","",IFERROR(INDEX('Parts Master'!$C:$C,MATCH(B28,'Parts Master'!$B:$B,0)),"Part Code not in Parts Master")) -> Nozzle Neck | D28: A | E28: 50 | F28: Edge Preparation / Beveling | G28: Weld end bevel prepared | H28: Fabrication Prep | I28: 12 | J28: 23 | K28: 0.35 | L28: Hours | M28: Per metre of edge | N28: No | P28: Bevel geometry and cleanliness meet drawing/WPS | Q28: Fit-up / bevel inspection report | R28: PROPOSED TIME / STAGE — validate by time study and approve before tracker load.
A29: PILOT – SOURCE DRAFT | B29: NOZ-01 | C29: =IF(B29="","",IFERROR(INDEX('Parts Master'!$C:$C,MATCH(B29,'Parts Master'!$B:$B,0)),"Part Code not in Parts Master")) -> Nozzle Neck | D29: A | E29: 60 | F29: Fit-up | G29: Neck fitted to flange or equipment | H29: Fabrication / Welding | I29: 19 | J29: 26 | K29: 1.5 | L29: Hours | M29: Per joint | N29: No | P29: Alignment, root gap, offset and orientation meet WPS/drawing | Q29: Fit-up report | R29: PROPOSED TIME / STAGE — validate by time study and approve before tracker load.
A30: PILOT – SOURCE DRAFT | B30: NOZ-01 | C30: =IF(B30="","",IFERROR(INDEX('Parts Master'!$C:$C,MATCH(B30,'Parts Master'!$B:$B,0)),"Part Code not in Parts Master")) -> Nozzle Neck | D30: A | E30: 70 | F30: Welding | G30: Neck joint welded | H30: Fabrication / Welding | I30: 20 | J30: 26 | K30: 1.2 | L30: Hours | M30: Per metre of weld | N30: No | P30: Weld completed to approved WPS by qualified welder; visual acceptable | Q30: Weld log / WPS / WPQ | R30: PROPOSED TIME / STAGE — validate by time study and approve before tracker load.
A31: PILOT – SOURCE DRAFT | B31: NOZ-01 | C31: =IF(B31="","",IFERROR(INDEX('Parts Master'!$C:$C,MATCH(B31,'Parts Master'!$B:$B,0)),"Part Code not in Parts Master")) -> Nozzle Neck | D31: A | E31: 80 | F31: NDT | G31: Joint examined by specified method | H31: Quality Control / QA | I31: 17 | J31: 28 | K31: 1 | L31: Hours | M31: Per joint | N31: Yes | O31: As required by job QAP | P31: Specified method and extent accepted to applicable code/QAP | Q31: NDE report | R31: PROPOSED TIME / STAGE — validate by time study and approve before tracker load.
A32: PILOT – SOURCE DRAFT | B32: NOZ-01 | C32: =IF(B32="","",IFERROR(INDEX('Parts Master'!$C:$C,MATCH(B32,'Parts Master'!$B:$B,0)),"Part Code not in Parts Master")) -> Nozzle Neck | D32: A | E32: 90 | F32: Inspection | G32: Projection and dimensions checked | H32: Quality Control / QA | I32: 21 | J32: 26 | K32: 0.75 | L32: Hours | M32: Per piece | N32: No | P32: Visual and dimensional results meet approved drawing/QAP | Q32: Dimensional / final inspection report | R32: PROPOSED TIME / STAGE — validate by time study and approve before tracker load.
A33: PILOT – SOURCE DRAFT | B33: FLG-01 | C33: =IF(B33="","",IFERROR(INDEX('Parts Master'!$C:$C,MATCH(B33,'Parts Master'!$B:$B,0)),"Part Code not in Parts Master")) -> Nozzle Flange | D33: A | E33: 10 | F33: Receipt | G33: Purchased flange or forging received | H33: Stores | I33: 10 | J33: 11 | K33: 0.5 | L33: Hours | M33: Per material lot | N33: No | P33: PO/BOM, packing list and visible condition acceptable | Q33: GRN / incoming inspection record | R33: PROPOSED TIME / STAGE — validate by time study and approve before tracker load.
A34: PILOT – SOURCE DRAFT | B34: FLG-01 | C34: =IF(B34="","",IFERROR(INDEX('Parts Master'!$C:$C,MATCH(B34,'Parts Master'!$B:$B,0)),"Part Code not in Parts Master")) -> Nozzle Flange | D34: A | E34: 20 | F34: MTC Verification / Material Identification | G34: MTC, grade and traceability verified | H34: Quality Control / QA | I34: 11 | J34: 12 | K34: 0.75 | L34: Hours | M34: Per material lot | N34: No | P34: Material specification, grade, heat/lot and traceability match PO/BOM | Q34: MTC review / PMI / traceability record | R34: PROPOSED TIME / STAGE — validate by time study and approve before tracker load.
A35: PILOT – SOURCE DRAFT | B35: FLG-01 | C35: =IF(B35="","",IFERROR(INDEX('Parts Master'!$C:$C,MATCH(B35,'Parts Master'!$B:$B,0)),"Part Code not in Parts Master")) -> Nozzle Flange | D35: A | E35: 30 | F35: NDT | G35: Incoming UT or other NDE reviewed/performed | H35: Quality Control / QA | I35: 17 | J35: 12 | K35: 1 | L35: Hours | M35: Per joint | N35: Yes | O35: If required for forging or by job specification | P35: Specified method and extent accepted to applicable code/QAP | Q35: NDE report | R35: PROPOSED TIME / STAGE — validate by time study and approve before tracker load.
A36: PILOT – SOURCE DRAFT | B36: FLG-01 | C36: =IF(B36="","",IFERROR(INDEX('Parts Master'!$C:$C,MATCH(B36,'Parts Master'!$B:$B,0)),"Part Code not in Parts Master")) -> Nozzle Flange | D36: A | E36: 40 | F36: Machining | G36: Bore, facing, drilling and final machining completed | H36: Machine Shop | I36: 14 | J36: 23 | K36: 2 | L36: Hours | M36: Per piece | N36: Yes | O36: If supplied rough or job machining is required | P36: Dimensions, tolerances and surface finish meet approved drawing | Q36: Machining inspection report | R36: PROPOSED TIME / STAGE — validate by time study and approve before tracker load.
A37: PILOT – SOURCE DRAFT | B37: FLG-01 | C37: =IF(B37="","",IFERROR(INDEX('Parts Master'!$C:$C,MATCH(B37,'Parts Master'!$B:$B,0)),"Part Code not in Parts Master")) -> Nozzle Flange | D37: A | E37: 50 | F37: Inspection | G37: Rating, facing and dimensions checked | H37: Quality Control / QA | I37: 21 | J37: 23 | K37: 0.75 | L37: Hours | M37: Per piece | N37: No | P37: Visual and dimensional results meet approved drawing/QAP | Q37: Dimensional / final inspection report | R37: PROPOSED TIME / STAGE — validate by time study and approve before tracker load.
A38: PILOT – SOURCE DRAFT | B38: TSH-01 | C38: =IF(B38="","",IFERROR(INDEX('Parts Master'!$C:$C,MATCH(B38,'Parts Master'!$B:$B,0)),"Part Code not in Parts Master")) -> Tube Sheet | D38: A | E38: 10 | F38: Receipt | G38: Tubesheet forging received | H38: Stores | J38: 11 | K38: 0.5 | L38: Hours | M38: Per material lot | N38: No | P38: PO/BOM, packing list and visible condition acceptable | Q38: GRN / incoming inspection record | R38: PROPOSED TIME / STAGE — validate by time study and approve before tracker load.
A39: PILOT – SOURCE DRAFT | B39: TSH-01 | C39: =IF(B39="","",IFERROR(INDEX('Parts Master'!$C:$C,MATCH(B39,'Parts Master'!$B:$B,0)),"Part Code not in Parts Master")) -> Tube Sheet | D39: A | E39: 20 | F39: MTC Verification / Material Identification | G39: MTC and vendor certificates reviewed | H39: Quality Control / QA | J39: 12 | K39: 0.75 | L39: Hours | M39: Per material lot | N39: No | P39: Material specification, grade, heat/lot and traceability match PO/BOM | Q39: MTC review / PMI / traceability record | R39: PROPOSED TIME / STAGE — validate by time study and approve before tracker load.
A40: PILOT – SOURCE DRAFT | B40: TSH-01 | C40: =IF(B40="","",IFERROR(INDEX('Parts Master'!$C:$C,MATCH(B40,'Parts Master'!$B:$B,0)),"Part Code not in Parts Master")) -> Tube Sheet | D40: A | E40: 30 | F40: NDT | G40: Forging UT reviewed or performed | H40: Quality Control / QA | J40: 12 | K40: 1 | L40: Hours | M40: Per joint | N40: No | P40: Specified method and extent accepted to applicable code/QAP | Q40: NDE report | R40: PROPOSED TIME / STAGE — validate by time study and approve before tracker load.
A41: PILOT – SOURCE DRAFT | B41: TSH-01 | C41: =IF(B41="","",IFERROR(INDEX('Parts Master'!$C:$C,MATCH(B41,'Parts Master'!$B:$B,0)),"Part Code not in Parts Master")) -> Tube Sheet | D41: A | E41: 40 | F41: Machining | G41: Rough machining completed | H41: Machine Shop | J41: 20 | K41: 0.08 | L41: Hours | M41: Per hole | N41: No | P41: Dimensions, tolerances and surface finish meet approved drawing | Q41: Machining inspection report | R41: PROPOSED TIME / STAGE — validate by time study and approve before tracker load.
...

Sheet Assembly Sequence
A1: REFERENCE + PROPOSED ASSEMBLY SEQUENCES — LIGHT-YELLOW PV ROWS ARE BASED ON APPROVED GA REV. C; WELD MAP AND METHODS REQUIRE APPROVAL.
A2: How parts are joined into sub-assemblies and then the complete equipment, in order, with weld joint references (LS-1, CS-2…) where applicable. One list per equipment type. The PV rows are real data from the DESPL-320 assembly sequence already in the tracker; the HE rows only show the format.
A4: Example? | B4: Equipment Type | C4: Group Code | D4: Group Name | E4: Step No. | F4: Seq | G4: Activity | H4: Kind | I4: Parts / Sub-assemblies used | J4: Result (sub-assembly produced) | K4: Weld Joint Ref. | L4: Department | M4: Counts toward Stage No. | N4: Remarks
A5: EXAMPLE (PV) | B5: Vertical PV (DESPL-320) | C5: E | D5: Shell Sub-Assembly (LS-1) | E5: 4.5 | F5: 13 | G5: Shell Weld Edge Preparation | H5: Work | I5: SHL-01 | L5: Fabrication / Welding | M5: 16 | N5: From the PV assembly sequence already in the tracker
A6: EXAMPLE (PV) | B6: Vertical PV (DESPL-320) | C6: E | D6: Shell Sub-Assembly (LS-1) | E6: 4.5 | F6: 14 | G6: L' Seam Set Up Of Shell (LS-1) Along With PTC | H6: Work | I6: SHL-01 | L6: Fabrication / Welding | M6: 16 | N6: From the PV assembly sequence already in the tracker
A7: EXAMPLE (PV) | B7: Vertical PV (DESPL-320) | C7: E | D7: Shell Sub-Assembly (LS-1) | E7: 4.5 | F7: 15 | G7: Weld Long Seam Of Shell (LS-1) | H7: Work | I7: SHL-01 | J7: Shell (LS-1 welded) | K7: LS-1 | L7: Fabrication / Welding | M7: 16 | N7: From the PV assembly sequence already in the tracker
A8: EXAMPLE (PV) | B8: Vertical PV (DESPL-320) | C8: E | D8: Shell Sub-Assembly (LS-1) | E8: 4.5 | F8: 16 | G8: Weld Visual Of LS-1 | H8: Inspection | L8: Quality Control / QA | M8: 17 | N8: From the PV assembly sequence already in the tracker
A9: EXAMPLE (PV) | B9: Vertical PV (DESPL-320) | C9: E | D9: Shell Sub-Assembly (LS-1) | E9: 4.5 | F9: 17 | G9: PAUT/TOFD Of LS-1 | H9: Inspection | L9: Quality Control / QA | M9: 17 | N9: From the PV assembly sequence already in the tracker
A10: EXAMPLE (PV) | B10: Vertical PV (DESPL-320) | C10: G | D10: Shell + Bottom Head (CS-2) | E10: 4.7 | F10: 22 | G10: Bottom Dished End To Shell Set Up (CS-2) | H10: Work | I10: Shell (LS-1 welded) + Bottom Dished End | J10: Shell + bottom head | L10: Fabrication / Welding | M10: 16 | N10: From the PV assembly sequence already in the tracker
A11: EXAMPLE (PV) | B11: Vertical PV (DESPL-320) | C11: G | D11: Shell + Bottom Head (CS-2) | E11: 4.7 | F11: 23 | G11: Weld Circ Seam Of Bottom Dishend To Shell (CS-2) | H11: Work | K11: CS-2 | L11: Fabrication / Welding | M11: 16 | N11: From the PV assembly sequence already in the tracker
A12: EXAMPLE (PV) | B12: Vertical PV (DESPL-320) | C12: G | D12: Shell + Bottom Head (CS-2) | E12: 4.7 | F12: 24 | G12: Weld Visual Of CS-2 | H12: Inspection | L12: Quality Control / QA | M12: 17 | N12: From the PV assembly sequence already in the tracker
A13: EXAMPLE (PV) | B13: Vertical PV (DESPL-320) | C13: G | D13: Shell + Bottom Head (CS-2) | E13: 4.7 | F13: 25 | G13: PAUT/TOFD Of CS-2 | H13: Inspection | L13: Quality Control / QA | M13: 17 | N13: From the PV assembly sequence already in the tracker
A14: DRAWING REQUIREMENT | B14: MED Train 1 (SP40) | C14: HD-L | D14: Left Dished Head Assembly | E14: 1.1 | F14: 10 | G14: Locate NSA2 reinforcement pad on left dished head per drawing | H14: Work | I14: HED-01 + RFP-01 | J14: Left head with NSA2 pad | N14: SP40-02-03-04-001 Sheet 01 Rev.0; joining method/department/stage require approval.
A15: DRAWING REQUIREMENT | B15: MED Train 1 (SP40) | C15: HD-R | D15: Right Dished Head Assembly | E15: 1.2 | F15: 10 | G15: Locate NSA3 reinforcement pad on right dished head per drawing | H15: Work | I15: HED-01 + RFP-01 | J15: Right head with NSA3 pad | N15: SP40-02-03-04-001 Sheet 02 Rev.0; joining method/department/stage require approval.
A16: DRAWING REQUIREMENT | B16: MED Train 1 (SP40) | C16: TB | D16: Tube-to-Tubesheet Joint | E16: 2.1 | F16: 10 | G16: Install food-grade EPDM grommets at tubesheet penetrations | H16: Work | I16: GRM-01 + TSH-02 | J16: Grommeted tubesheets | N16: SP40-02-02-11-04/-05 Rev.0; operation ownership and stage pending.
A17: DRAWING REQUIREMENT | B17: MED Train 1 (SP40) | C17: TB | D17: Tube-to-Tubesheet Joint | E17: 2.1 | F17: 20 | G17: Pass Ø21.3 tubes through 10 mm tubesheets and grommets to drawing lengths | H17: Work | I17: TUB-01 + GRM-01 + TSH-02 | J17: Tube/tubesheet assembly | N17: Drawing states tight fit with grommets; no expansion or seal welding is specified.
